Workbook

Sheet Guide
A1: HƯỚNG DẪN — Ô NÀO NHẬP TAY, Ô NÀO TỰ TÍNH
A3: QUY ƯỚC MÀU
A4: Chữ XANH DƯƠNG + nền vàng | B4: Ô INPUT — bạn nhập tay
A5: Chữ ĐEN | B5: Công thức tính trong cùng sheet — KHÔNG sửa
A6: Chữ XANH LÁ | B6: Công thức link sang sheet khác — KHÔNG sửa
A8: THỨ TỰ NHẬP LIỆU
A9: 1. Sheet "Margin Analysis" — điền thông tin đơn hàng (B3:B9) và bảng PRICING PARAMETERS (F3:F13).
A10: 2. Sheet "Logistic" — điền FREIGHT, Clearance, Inland, Chargeable weight cho từng shipment.
A11: 3. Sheet "Bank Fee" — điền Rate, Min fee, và Base amount của International receive (F6).
A12: 4. Sheet "Margin Analysis" — điền danh mục hàng: cột A–F, H, I của mỗi block.
A13: 5. Toàn bộ DDP Price, Margin, Total Revenue tự động chạy ra. Không cần dò tay giá bán.
A15: BẢN ĐỒ INPUT / CÔNG THỨC
A16: SHEET | B16: Ô / CỘT | C16: INDICATOR | D16: LOẠI | E16: CÔNG THỨC / GHI CHÚ
A17: Margin Analysis | B17: B3:B9 | C17: Job No., Customer, Country, Goods origin, Incoterm, Payment terms, Inquiry date | D17: INPUT | E17: B5 (Country) và B6 (Goods origin) điều khiển công thức ở sheet Bank Fee
A18: Margin Analysis | B18: F3 | C18: Exchange rate (quote) USD→VND | D18: INPUT | E18: Dùng để quy DDP USD sang VND
A19: Margin Analysis | B19: F4 | C19: Exchange rate (booking) USD→VND | D19: INPUT | E19: Chỉ dùng cho phần tính margin thực tế
A20: Margin Analysis | B20: F5 | C20: Target margin (m) | D20: INPUT | E20: Đổi ô này → toàn bộ giá bán tự tính lại
A21: Margin Analysis | B21: F6 | C21: Commission rate (q) | D21: INPUT | E21: Tính trên giá bán
A22: Margin Analysis | B22: F7 | C22: CIT on commission (c) | D22: INPUT | E22: Thuế nhà thầu
A23: Margin Analysis | B23: F8:F11 | C23: % Value financed, Interest rate, Financing days, Days per year | D23: INPUT | E23: Cấu thành chi phí vốn ở cột J
A24: Margin Analysis | B24: F12 | C24: VND rounding step | D24: INPUT | E24: 10.000 = làm tròn lên chục nghìn
A25: Margin Analysis | B25: F13 | C25: Conversion factor lb → kg | D25: INPUT | E25: Đặt = 1 nếu cột F nhập bằng kg
A26: Margin Analysis | B26: A:F, H, I | C26: ITEM, Part No., Description, Supplier, Q'ty, Total Weight (lb), Material Cost, %Duty | D26: INPUT | E26: Đây là 8 cột duy nhất phải nhập cho mỗi dòng hàng
A27: Margin Analysis | B27: G | C27: Weight (kg) / đơn vị | D27: CÔNG THỨC | E27: → Total Weight (lb) ÷ Q'ty × Conversion factor
... A58: Bank Fee | B58: H8 | C58: TOTAL BANK FEE | D58: CÔNG THỨC | E58: → SUM(H5:H7) → phân bổ sang cột J của Margin Analysis

Sheet Margin Analysis
A1: MARGIN ANALYSIS – TÍNH GIÁ DDP
E2: PRICING PARAMETERS (ô vàng = input)
A3: Job No. | B3: AC0084-PCS-OTHVN | E3: Exchange rate (quote) USD→VND | F3: 26500 | G3: Quy DDP USD sang VND
A4: Customer | B4: Hoang Son | E4: Exchange rate (booking) USD→VND | F4: 26445 | G4: Tỷ giá ghi nhận thực tế
A5: Country | B5: VN | E5: Target margin (m) | F5: 0.25 | G5: Lãi gộp trên giá bán
A6: Goods origin | B6: Oversea | E6: Commission rate (q) | F6: 0.03 | G6: Tính trên giá bán DDP USD
A7: Incoterm | B7: DDP Vung Tau | E7: CIT on commission (c) | F7: % | G7: Thuế nhà thầu trên hoa hồng
A8: Payment terms | B8: 30% with order, 70% prior shipment | E8: % Value financed | F8: 0.5 | G8: Theo điều khoản 30/70
A9: Inquiry date | B9: 2026-08-09 | E9: Interest rate p.a. | F9: 0.15 | G9: Chi phí vốn
E10: Financing days | F10: 15 | G10: Số ngày tài trợ vốn
A11: Ghi chú: chữ XANH DƯƠNG = ô nhập tay · chữ ĐEN = công thức · chữ XANH LÁ = link sang sheet khác | E11: Days per year | F11: 360 | G11: Cơ sở quy đổi lãi
E12: VND rounding step | F12: 10000 | G12: Giá VND làm tròn LÊN bội số này
A13: BLOCK 1 — AIR FREIGHT | E13: Conversion factor lb → kg | F13: 0.4536 | G13: Đặt = 1 nếu cột KL đã nhập bằng kg
A14: ITEM | B14: Part No. | C14: Description | D14: Supplier | E14: Q'ty | F14: Total Weight (lb) | G14: Weight (kg) | H14: Material Cost | I14: %Duty | J14: Bank fee | K14: Logistics | L14: Duty | M14: Commission | N14: CIT | O14: Unit Cost | P14: DDP Price (USD) | Q14: DDP Price (VND) | R14: Total Revenue (VND) | S14: Margin per unit | T14: % Margin | U14: Total Margin | V14: Total Cost
A15: 1 | B15: A23-170 | C15: (2633) 7 5/8" - 9 5/8" BASIC INSERT | D15: Keystone | E15: 320 | F15: 121.6 | G15: =IF($E15=0,0,$F15/$E15*$F$13) -> 0.172368 | H15: 4.37 | I15: 0 | J15: =$H15*$F$8*($F$9*$F$10/$F$11)+IF($H$31=0,0,'Bank Fee'!$H$8*$H15/$H$31) -> 0.024994413 | K15: =IF($G$31=0,0,(Logistic!$M$5+Logistic!$R$5)*$G15/$G$31) -> 0.67122745 | L15: =($H15+$K15)*$I15 -> 0 | M15: =$F$6*$P15 -> #VALUE! | N15: =$F$7*$M15 -> #VALUE! | O15: =$H15+$J15+$K15+$L15+$M15+$N15 -> #VALUE! | P15: =ROUNDUP(($H15+$J15+$K15+$L15)/(1-$F$5-$F$6*(1+$F$7)),2) -> #VALUE! | Q15: =ROUNDUP($P15*$F$3/$F$12,0)*$F$12 -> #VALUE! | R15: =$E15*$Q15 -> #VALUE! | S15: =$P15-$O15 -> #VALUE! | T15: =IF($P15=0,0,$S15/$P15) -> #VALUE! | U15: =$E15*$S15 -> #VALUE! | V15: =$E15*$O15 -> #VALUE!
A16: 2 | B16: A23-170-B | C16: 7 5/8" - 9 5/8" BEVELED BASIC INSERT (2633-B) | D16: Keystone | E16: 160 | F16: 67.2 | G16: =IF($E16=0,0,$F16/$E16*$F$13) -> 0.190512 | H16: 4.68 | I16: 0 | J16: =$H16*$F$8*($F$9*$F$10/$F$11)+IF($H$31=0,0,'Bank Fee'!$H$8*$H16/$H$31) -> 0.026767472 | K16: =IF($G$31=0,0,(Logistic!$M$5+Logistic!$R$5)*$G16/$G$31) -> 0.74188297 | L16: =($H16+$K16)*$I16 -> 0 | M16: =$F$6*$P16 -> #VALUE! | N16: =$F$7*$M16 -> #VALUE! | O16: =$H16+$J16+$K16+$L16+$M16+$N16 -> #VALUE! | P16: =ROUNDUP(($H16+$J16+$K16+$L16)/(1-$F$5-$F$6*(1+$F$7)),2) -> #VALUE! | Q16: =ROUNDUP($P16*$F$3/$F$12,0)*$F$12 -> #VALUE! | R16: =$E16*$Q16 -> #VALUE! | S16: =$P16-$O16 -> #VALUE! | T16: =IF($P16=0,0,$S16/$P16) -> #VALUE! | U16: =$E16*$S16 -> #VALUE! | V16: =$E16*$O16 -> #VALUE!
A17: 3 | B17: A23-186 | C17: (2649) SD INSERT ''UNDERSIZED'' | D17: Keystone | E17: 320 | F17: 102.4 | G17: =IF($E17=0,0,$F17/$E17*$F$13) -> 0.145152 | H17: 4.81 | I17: 0 | J17: =$H17*$F$8*($F$9*$F$10/$F$11)+IF($H$31=0,0,'Bank Fee'!$H$8*$H17/$H$31) -> 0.027511013 | K17: =IF($G$31=0,0,(Logistic!$M$5+Logistic!$R$5)*$G17/$G$31) -> 0.56524417 | L17: =($H17+$K17)*$I17 -> 0 | M17: =$F$6*$P17 -> #VALUE! | N17: =$F$7*$M17 -> #VALUE! | O17: =$H17+$J17+$K17+$L17+$M17+$N17 -> #VALUE! | P17: =ROUNDUP(($H17+$J17+$K17+$L17)/(1-$F$5-$F$6*(1+$F$7)),2) -> #VALUE! | Q17: =ROUNDUP($P17*$F$3/$F$12,0)*$F$12 -> #VALUE! | R17: =$E17*$Q17 -> #VALUE! | S17: =$P17-$O17 -> #VALUE! | T17: =IF($P17=0,0,$S17/$P17) -> #VALUE! | U17: =$E17*$S17 -> #VALUE! | V17: =$E17*$O17 -> #VALUE!
A18: 4 | B18: A23-186-B | C18: (2649B) SD BEVELED INSERT BEVELED | D18: Keystone | E18: 160 | F18: 148 | G18: =IF($E18=0,0,$F18/$E18*$F$13) -> 0.41958 | H18: 5.19 | I18: 0 | J18: =$H18*$F$8*($F$9*$F$10/$F$11)+IF($H$31=0,0,'Bank Fee'!$H$8*$H18/$H$31) -> 0.02968444 | K18: =IF($G$31=0,0,(Logistic!$M$5+Logistic!$R$5)*$G18/$G$31) -> 1.6339089 | L18: =($H18+$K18)*$I18 -> 0 | M18: =$F$6*$P18 -> #VALUE! | N18: =$F$7*$M18 -> #VALUE! | O18: =$H18+$J18+$K18+$L18+$M18+$N18 -> #VALUE! | P18: =ROUNDUP(($H18+$J18+$K18+$L18)/(1-$F$5-$F$6*(1+$F$7)),2) -> #VALUE! | Q18: =ROUNDUP($P18*$F$3/$F$12,0)*$F$12 -> #VALUE! | R18: =$E18*$Q18 -> #VALUE! | S18: =$P18-$O18 -> #VALUE! | T18: =IF($P18=0,0,$S18/$P18) -> #VALUE! | U18: =$E18*$S18 -> #VALUE! | V18: =$E18*$O18 -> #VALUE!
A19: 5 | B19: A23-172 | C19: (2637) 11 3/4" - 13 3/8" BASIC INSERT | D19: Keystone | E19: 400 | F19: 148 | G19: =IF($E19=0,0,$F19/$E19*$F$13) -> 0.167832 | H19: 4.37 | I19: 0 | J19: =$H19*$F$8*($F$9*$F$10/$F$11)+IF($H$31=0,0,'Bank Fee'!$H$8*$H19/$H$31) -> 0.024994413 | K19: =IF($G$31=0,0,(Logistic!$M$5+Logistic!$R$5)*$G19/$G$31) -> 0.65356357 | L19: =($H19+$K19)*$I19 -> 0 | M19: =$F$6*$P19 -> #VALUE! | N19: =$F$7*$M19 -> #VALUE! | O19: =$H19+$J19+$K19+$L19+$M19+$N19 -> #VALUE! | P19: =ROUNDUP(($H19+$J19+$K19+$L19)/(1-$F$5-$F$6*(1+$F$7)),2) -> #VALUE! | Q19: =ROUNDUP($P19*$F$3/$F$12,0)*$F$12 -> #VALUE! | R19: =$E19*$Q19 -> #VALUE! | S19: =$P19-$O19 -> #VALUE! | T19: =IF($P19=0,0,$S19/$P19) -> #VALUE! | U19: =$E19*$S19 -> #VALUE! | V19: =$E19*$O19 -> #VALUE!
A20: 6 | B20: A23-172-B | C20: (2637B) 11-3/4" x 11-3/4" SD BEVELED INSERT | D20: Keystone | E20: 200 | F20: 185 | G20: =IF($E20=0,0,$F20/$E20*$F$13) -> 0.41958 | H20: 4.68 | I20: 0 | J20: =$H20*$F$8*($F$9*$F$10/$F$11)+IF($H$31=0,0,'Bank Fee'!$H$8*$H20/$H$31) -> 0.026767472 | K20: =IF($G$31=0,0,(Logistic!$M$5+Logistic!$R$5)*$G20/$G$31) -> 1.6339089 | L20: =($H20+$K20)*$I20 -> 0 | M20: =$F$6*$P20 -> #VALUE! | N20: =$F$7*$M20 -> #VALUE! | O20: =$H20+$J20+$K20+$L20+$M20+$N20 -> #VALUE! | P20: =ROUNDUP(($H20+$J20+$K20+$L20)/(1-$F$5-$F$6*(1+$F$7)),2) -> #VALUE! | Q20: =ROUNDUP($P20*$F$3/$F$12,0)*$F$12 -> #VALUE! | R20: =$E20*$Q20 -> #VALUE! | S20: =$P20-$O20 -> #VALUE! | T20: =IF($P20=0,0,$S20/$P20) -> #VALUE! | U20: =$E20*$S20 -> #VALUE! | V20: =$E20*$O20 -> #VALUE!
A21: 7 | B21: A23-171 | C21: (2640) 9 5/8" X 8 5/8" SD INSERT | D21: Keystone | E21: 400 | F21: 304 | G21: =IF($E21=0,0,$F21/$E21*$F$13) -> 0.344736 | H21: 4.37 | I21: 0 | J21: =$H21*$F$8*($F$9*$F$10/$F$11)+IF($H$31=0,0,'Bank Fee'!$H$8*$H21/$H$31) -> 0.024994413 | K21: =IF($G$31=0,0,(Logistic!$M$5+Logistic!$R$5)*$G21/$G$31) -> 1.3424549 | L21: =($H21+$K21)*$I21 -> 0 | M21: =$F$6*$P21 -> #VALUE! | N21: =$F$7*$M21 -> #VALUE! | O21: =$H21+$J21+$K21+$L21+$M21+$N21 -> #VALUE! | P21: =ROUNDUP(($H21+$J21+$K21+$L21)/(1-$F$5-$F$6*(1+$F$7)),2) -> #VALUE! | Q21: =ROUNDUP($P21*$F$3/$F$12,0)*$F$12 -> #VALUE! | R21: =$E21*$Q21 -> #VALUE! | S21: =$P21-$O21 -> #VALUE! | T21: =IF($P21=0,0,$S21/$P21) -> #VALUE! | U21: =$E21*$S21 -> #VALUE! | V21: =$E21*$O21 -> #VALUE!
A22: 8 | B22: A23-171-B | C22: (2640) 9 5/8" X 8 5/8" SD BEVELED REDUCING INSERT | D22: Keystone | E22: 200 | F22: 150 | G22: =IF($E22=0,0,$F22/$E22*$F$13) -> 0.3402 | H22: 4.68 | I22: 0 | J22: =$H22*$F$8*($F$9*$F$10/$F$11)+IF($H$31=0,0,'Bank Fee'!$H$8*$H22/$H$31) -> 0.026767472 | K22: =IF($G$31=0,0,(Logistic!$M$5+Logistic!$R$5)*$G22/$G$31) -> 1.324791 | L22: =($H22+$K22)*$I22 -> 0 | M22: =$F$6*$P22 -> #VALUE! | N22: =$F$7*$M22 -> #VALUE! | O22: =$H22+$J22+$K22+$L22+$M22+$N22 -> #VALUE! | P22: =ROUNDUP(($H22+$J22+$K22+$L22)/(1-$F$5-$F$6*(1+$F$7)),2) -> #VALUE! | Q22: =ROUNDUP($P22*$F$3/$F$12,0)*$F$12 -> #VALUE! | R22: =$E22*$Q22 -> #VALUE! | S22: =$P22-$O22 -> #VALUE! | T22: =IF($P22=0,0,$S22/$P22) -> #VALUE! | U22: =$E22*$S22 -> #VALUE! | V22: =$E22*$O22 -> #VALUE!
A23: 9 | B23: A23-173 | C23: (2636) 14" X 13 3/8" SD INSERT | D23: Keystone | E23: 400 | F23: 248 | G23: =IF($E23=0,0,$F23/$E23*$F$13) -> 0.281232 | H23: 4.55 | I23: 0 | J23: =$H23*$F$8*($F$9*$F$10/$F$11)+IF($H$31=0,0,'Bank Fee'!$H$8*$H23/$H$31) -> 0.026023931 | K23: =IF($G$31=0,0,(Logistic!$M$5+Logistic!$R$5)*$G23/$G$31) -> 1.0951606 | L23: =($H23+$K23)*$I23 -> 0 | M23: =$F$6*$P23 -> #VALUE! | N23: =$F$7*$M23 -> #VALUE! | O23: =$H23+$J23+$K23+$L23+$M23+$N23 -> #VALUE! | P23: =ROUNDUP(($H23+$J23+$K23+$L23)/(1-$F$5-$F$6*(1+$F$7)),2) -> #VALUE! | Q23: =ROUNDUP($P23*$F$3/$F$12,0)*$F$12 -> #VALUE! | R23: =$E23*$Q23 -> #VALUE! | S23: =$P23-$O23 -> #VALUE! | T23: =IF($P23=0,0,$S23/$P23) -> #VALUE! | U23: =$E23*$S23 -> #VALUE! | V23: =$E23*$O23 -> #VALUE!
A24: 10 | B24: A23-173-B | C24: (2636) 14" X 13 3/8" SD BEVELED INSERT | D24: Keystone | E24: 200 | F24: 128 | G24: =IF($E24=0,0,$F24/$E24*$F$13) -> 0.290304 | H24: 4.73 | I24: 0 | J24: =$H24*$F$8*($F$9*$F$10/$F$11)+IF($H$31=0,0,'Bank Fee'!$H$8*$H24/$H$31) -> 0.027053449 | K24: =IF($G$31=0,0,(Logistic!$M$5+Logistic!$R$5)*$G24/$G$31) -> 1.1304883 | L24: =($H24+$K24)*$I24 -> 0 | M24: =$F$6*$P24 -> #VALUE! | N24: =$F$7*$M24 -> #VALUE! | O24: =$H24+$J24+$K24+$L24+$M24+$N24 -> #VALUE! | P24: =ROUNDUP(($H24+$J24+$K24+$L24)/(1-$F$5-$F$6*(1+$F$7)),2) -> #VALUE! | Q24: =ROUNDUP($P24*$F$3/$F$12,0)*$F$12 -> #VALUE! | R24: =$E24*$Q24 -> #VALUE! | S24: =$P24-$O24 -> #VALUE! | T24: =IF($P24=0,0,$S24/$P24) -> #VALUE! | U24: =$E24*$S24 -> #VALUE! | V24: =$E24*$O24 -> #VALUE!
A25: 11 | B25: A23-180 | C25: (2653) 14" X 13 5/8" SD INSERT | D25: Keystone | E25: 400 | F25: 212 | G25: =IF($E25=0,0,$F25/$E25*$F$13) -> 0.240408 | H25: 4.87 | I25: 0 | J25: =$H25*$F$8*($F$9*$F$10/$F$11)+IF($H$31=0,0,'Bank Fee'!$H$8*$H25/$H$31) -> 0.027854185 | K25: =IF($G$31=0,0,(Logistic!$M$5+Logistic!$R$5)*$G25/$G$31) -> 0.93618566 | L25: =($H25+$K25)*$I25 -> 0 | M25: =$F$6*$P25 -> #VALUE! | N25: =$F$7*$M25 -> #VALUE! | O25: =$H25+$J25+$K25+$L25+$M25+$N25 -> #VALUE! | P25: =ROUNDUP(($H25+$J25+$K25+$L25)/(1-$F$5-$F$6*(1+$F$7)),2) -> #VALUE! | Q25: =ROUNDUP($P25*$F$3/$F$12,0)*$F$12 -> #VALUE! | R25: =$E25*$Q25 -> #VALUE! | S25: =$P25-$O25 -> #VALUE! | T25: =IF($P25=0,0,$S25/$P25) -> #VALUE! | U25: =$E25*$S25 -> #VALUE! | V25: =$E25*$O25 -> #VALUE!
A26: 12 | B26: A23-180-B | C26: (2653) 14" X 13 5/8" BEVELED SD INSERT | D26: Keystone | E26: 200 | F26: 102 | G26: =IF($E26=0,0,$F26/$E26*$F$13) -> 0.231336 | H26: 6.46 | I26: 0 | J26: =$H26*$F$8*($F$9*$F$10/$F$11)+IF($H$31=0,0,'Bank Fee'!$H$8*$H26/$H$31) -> 0.036948262 | K26: =IF($G$31=0,0,(Logistic!$M$5+Logistic!$R$5)*$G26/$G$31) -> 0.9008579 | L26: =($H26+$K26)*$I26 -> 0 | M26: =$F$6*$P26 -> #VALUE! | N26: =$F$7*$M26 -> #VALUE! | O26: =$H26+$J26+$K26+$L26+$M26+$N26 -> #VALUE! | P26: =ROUNDUP(($H26+$J26+$K26+$L26)/(1-$F$5-$F$6*(1+$F$7)),2) -> #VALUE! | Q26: =ROUNDUP($P26*$F$3/$F$12,0)*$F$12 -> #VALUE! | R26: =$E26*$Q26 -> #VALUE! | S26: =$P26-$O26 -> #VALUE! | T26: =IF($P26=0,0,$S26/$P26) -> #VALUE! | U26: =$E26*$S26 -> #VALUE! | V26: =$E26*$O26 -> #VALUE!
... A30: 16 | B30: A23-170-B | C30: 7 5/8" - 9 5/8" BEVELED BASIC INSERT (2633-B) | D30: Keystone | E30: 120 | F30: 50.4 | G30: =IF($E30=0,0,$F30/$E30*$F$13) -> 0.190512 | H30: 4.68 | I30: 0 | J30: =$H30*$F$8*($F$9*$F$10/$F$11)+IF($H$31=0,0,'Bank Fee'!$H$8*$H30/$H$31) -> 0.026767472 | K30: =IF($G$31=0,0,(Logistic!$M$5+Logistic!$R$5)*$G30/$G$31) -> 0.74188297 | L30: =($H30+$K30)*$I30 -> 0 | M30: =$F$6*$P30 -> #VALUE! | N30: =$F$7*$M30 -> #VALUE! | O30: =$H30+$J30+$K30+$L30+$M30+$N30 -> #VALUE! | P30: =ROUNDUP(($H30+$J30+$K30+$L30)/(1-$F$5-$F$6*(1+$F$7)),2) -> #VALUE! | Q30: =ROUNDUP($P30*$F$3/$F$12,0)*$F$12 -> #VALUE! | R30: =$E30*$Q30 -> #VALUE! | S30: =$P30-$O30 -> #VALUE! | T30: =IF($P30=0,0,$S30/$P30) -> #VALUE! | U30: =$E30*$S30 -> #VALUE! | V30: =$E30*$O30 -> #VALUE!
A31: TOTAL | E31: =SUM(E15:E30) -> 4080 | F31: =SUM(F15:F30) -> 2273 | G31: =SUMPRODUCT($E$15:$E$30,G15:G30) -> 1031.0328 | H31: =SUMPRODUCT($E$15:$E$30,H15:H30) -> 19271.2 | J31: =SUMPRODUCT($E$15:$E$30,J15:J30) -> 110.2225 | K31: =SUMPRODUCT($E$15:$E$30,K15:K30) -> 4015 | L31: =SUMPRODUCT($E$15:$E$30,L15:L30) -> 0 | M31: =SUMPRODUCT($E$15:$E$30,M15:M30) -> #VALUE! | N31: =SUMPRODUCT($E$15:$E$30,N15:N30) -> #VALUE! | O31: =SUMPRODUCT($E$15:$E$30,O15:O30) -> #VALUE! | P31: =SUMPRODUCT($E$15:$E$30,P15:P30) -> #VALUE! | R31: =SUM(R15:R30) -> #VALUE! | T31: =IF(P31=0,0,U31/P31) -> #VALUE! | U31: =SUM(U15:U30) -> #VALUE! | V31: =SUM(V15:V30) -> #VALUE!
A34: BLOCK 2 — SEA FREIGHT
A35: ITEM | B35: Part No. | C35: Description | D35: Supplier | E35: Q'ty | F35: Total Weight (lb) | G35: Weight (kg) | H35: Material Cost | I35: %Duty | J35: Bank fee | K35: Logistics | L35: Duty | M35: Commission | N35: CIT | O35: Unit Cost | P35: DDP Price (USD) | Q35: DDP Price (VND) | R35: Total Revenue (VND) | S35: Margin per unit | T35: % Margin | U35: Total Margin | V35: Total Cost
A36: 1 | B36: A23-170 | C36: (2633) 7 5/8" - 9 5/8" BASIC INSERT | D36: Keystone | E36: 320 | F36: 121.6 | G36: =IF($E36=0,0,$F36/$E36*$F$13) -> 0.172368 | H36: 4.37 | I36: 0 | J36: =$H36*$F$8*($F$9*$F$10/$F$11)+IF($H$52=0,0,'Bank Fee'!$H$8*$H36/$H$52) -> 0.024994413 | K36: =IF($G$52=0,0,(Logistic!$M$6+Logistic!$R$6)*$G36/$G$52) -> 0.17804663 | L36: =($H36+$K36)*$I36 -> 0 | M36: =$F$6*$P36 -> #VALUE! | N36: =$F$7*$M36 -> #VALUE! | O36: =$H36+$J36+$K36+$L36+$M36+$N36 -> #VALUE! | P36: =ROUNDUP(($H36+$J36+$K36+$L36)/(1-$F$5-$F$6*(1+$F$7)),2) -> #VALUE! | Q36: =ROUNDUP($P36*$F$3/$F$12,0)*$F$12 -> #VALUE! | R36: =$E36*$Q36 -> #VALUE! | S36: =$P36-$O36 -> #VALUE! | T36: =IF($P36=0,0,$S36/$P36) -> #VALUE! | U36: =$E36*$S36 -> #VALUE! | V36: =$E36*$O36 -> #VALUE!
A37: 2 | B37: A23-170-B | C37: 7 5/8" - 9 5/8" BEVELED BASIC INSERT (2633-B) | D37: Keystone | E37: 160 | F37: 67.2 | G37: =IF($E37=0,0,$F37/$E37*$F$13) -> 0.190512 | H37: 4.68 | I37: 0 | J37: =$H37*$F$8*($F$9*$F$10/$F$11)+IF($H$52=0,0,'Bank Fee'!$H$8*$H37/$H$52) -> 0.026767472 | K37: =IF($G$52=0,0,(Logistic!$M$6+Logistic!$R$6)*$G37/$G$52) -> 0.19678839 | L37: =($H37+$K37)*$I37 -> 0 | M37: =$F$6*$P37 -> #VALUE! | N37: =$F$7*$M37 -> #VALUE! | O37: =$H37+$J37+$K37+$L37+$M37+$N37 -> #VALUE! | P37: =ROUNDUP(($H37+$J37+$K37+$L37)/(1-$F$5-$F$6*(1+$F$7)),2) -> #VALUE! | Q37: =ROUNDUP($P37*$F$3/$F$12,0)*$F$12 -> #VALUE! | R37: =$E37*$Q37 -> #VALUE! | S37: =$P37-$O37 -> #VALUE! | T37: =IF($P37=0,0,$S37/$P37) -> #VALUE! | U37: =$E37*$S37 -> #VALUE! | V37: =$E37*$O37 -> #VALUE!
A38: 3 | B38: A23-186 | C38: (2649) SD INSERT ''UNDERSIZED'' | D38: Keystone | E38: 320 | F38: 102.4 | G38: =IF($E38=0,0,$F38/$E38*$F$13) -> 0.145152 | H38: 4.81 | I38: 0 | J38: =$H38*$F$8*($F$9*$F$10/$F$11)+IF($H$52=0,0,'Bank Fee'!$H$8*$H38/$H$52) -> 0.027511013 | K38: =IF($G$52=0,0,(Logistic!$M$6+Logistic!$R$6)*$G38/$G$52) -> 0.14993401 | L38: =($H38+$K38)*$I38 -> 0 | M38: =$F$6*$P38 -> #VALUE! | N38: =$F$7*$M38 -> #VALUE! | O38: =$H38+$J38+$K38+$L38+$M38+$N38 -> #VALUE! | P38: =ROUNDUP(($H38+$J38+$K38+$L38)/(1-$F$5-$F$6*(1+$F$7)),2) -> #VALUE! | Q38: =ROUNDUP($P38*$F$3/$F$12,0)*$F$12 -> #VALUE! | R38: =$E38*$Q38 -> #VALUE! | S38: =$P38-$O38 -> #VALUE! | T38: =IF($P38=0,0,$S38/$P38) -> #VALUE! | U38: =$E38*$S38 -> #VALUE! | V38: =$E38*$O38 -> #VALUE!
A39: 4 | B39: A23-186-B | C39: (2649B) SD BEVELED INSERT BEVELED | D39: Keystone | E39: 160 | F39: 148 | G39: =IF($E39=0,0,$F39/$E39*$F$13) -> 0.41958 | H39: 5.19 | I39: 0 | J39: =$H39*$F$8*($F$9*$F$10/$F$11)+IF($H$52=0,0,'Bank Fee'!$H$8*$H39/$H$52) -> 0.02968444 | K39: =IF($G$52=0,0,(Logistic!$M$6+Logistic!$R$6)*$G39/$G$52) -> 0.43340299 | L39: =($H39+$K39)*$I39 -> 0 | M39: =$F$6*$P39 -> #VALUE! | N39: =$F$7*$M39 -> #VALUE! | O39: =$H39+$J39+$K39+$L39+$M39+$N39 -> #VALUE! | P39: =ROUNDUP(($H39+$J39+$K39+$L39)/(1-$F$5-$F$6*(1+$F$7)),2) -> #VALUE! | Q39: =ROUNDUP($P39*$F$3/$F$12,0)*$F$12 -> #VALUE! | R39: =$E39*$Q39 -> #VALUE! | S39: =$P39-$O39 -> #VALUE! | T39: =IF($P39=0,0,$S39/$P39) -> #VALUE! | U39: =$E39*$S39 -> #VALUE! | V39: =$E39*$O39 -> #VALUE!
A40: 5 | B40: A23-172 | C40: (2637) 11 3/4" - 13 3/8" BASIC INSERT | D40: Keystone | E40: 400 | F40: 148 | G40: =IF($E40=0,0,$F40/$E40*$F$13) -> 0.167832 | H40: 4.37 | I40: 0 | J40: =$H40*$F$8*($F$9*$F$10/$F$11)+IF($H$52=0,0,'Bank Fee'!$H$8*$H40/$H$52) -> 0.024994413 | K40: =IF($G$52=0,0,(Logistic!$M$6+Logistic!$R$6)*$G40/$G$52) -> 0.1733612 | L40: =($H40+$K40)*$I40 -> 0 | M40: =$F$6*$P40 -> #VALUE! | N40: =$F$7*$M40 -> #VALUE! | O40: =$H40+$J40+$K40+$L40+$M40+$N40 -> #VALUE! | P40: =ROUNDUP(($H40+$J40+$K40+$L40)/(1-$F$5-$F$6*(1+$F$7)),2) -> #VALUE! | Q40: =ROUNDUP($P40*$F$3/$F$12,0)*$F$12 -> #VALUE! | R40: =$E40*$Q40 -> #VALUE! | S40: =$P40-$O40 -> #VALUE! | T40: =IF($P40=0,0,$S40/$P40) -> #VALUE! | U40: =$E40*$S40 -> #VALUE! | V40: =$E40*$O40 -> #VALUE!
A41: 6 | B41: A23-172-B | C41: (2637B) 11-3/4" x 11-3/4" SD BEVELED INSERT | D41: Keystone | E41: 200 | F41: 185 | G41: =IF($E41=0,0,$F41/$E41*$F$13) -> 0.41958 | H41: 4.68 | I41: 0 | J41: =$H41*$F$8*($F$9*$F$10/$F$11)+IF($H$52=0,0,'Bank Fee'!$H$8*$H41/$H$52) -> 0.026767472 | K41: =IF($G$52=0,0,(Logistic!$M$6+Logistic!$R$6)*$G41/$G$52) -> 0.43340299 | L41: =($H41+$K41)*$I41 -> 0 | M41: =$F$6*$P41 -> #VALUE! | N41: =$F$7*$M41 -> #VALUE! | O41: =$H41+$J41+$K41+$L41+$M41+$N41 -> #VALUE! | P41: =ROUNDUP(($H41+$J41+$K41+$L41)/(1-$F$5-$F$6*(1+$F$7)),2) -> #VALUE! | Q41: =ROUNDUP($P41*$F$3/$F$12,0)*$F$12 -> #VALUE! | R41: =$E41*$Q41 -> #VALUE! | S41: =$P41-$O41 -> #VALUE! | T41: =IF($P41=0,0,$S41/$P41) -> #VALUE! | U41: =$E41*$S41 -> #VALUE! | V41: =$E41*$O41 -> #VALUE!
A42: 7 | B42: A23-171 | C42: (2640) 9 5/8" X 8 5/8" SD INSERT | D42: Keystone | E42: 400 | F42: 304 | G42: =IF($E42=0,0,$F42/$E42*$F$13) -> 0.344736 | H42: 4.37 | I42: 0 | J42: =$H42*$F$8*($F$9*$F$10/$F$11)+IF($H$52=0,0,'Bank Fee'!$H$8*$H42/$H$52) -> 0.024994413 | K42: =IF($G$52=0,0,(Logistic!$M$6+Logistic!$R$6)*$G42/$G$52) -> 0.35609327 | L42: =($H42+$K42)*$I42 -> 0 | M42: =$F$6*$P42 -> #VALUE! | N42: =$F$7*$M42 -> #VALUE! | O42: =$H42+$J42+$K42+$L42+$M42+$N42 -> #VALUE! | P42: =ROUNDUP(($H42+$J42+$K42+$L42)/(1-$F$5-$F$6*(1+$F$7)),2) -> #VALUE! | Q42: =ROUNDUP($P42*$F$3/$F$12,0)*$F$12 -> #VALUE! | R42: =$E42*$Q42 -> #VALUE! | S42: =$P42-$O42 -> #VALUE! | T42: =IF($P42=0,0,$S42/$P42) -> #VALUE! | U42: =$E42*$S42 -> #VALUE! | V42: =$E42*$O42 -> #VALUE!
A43: 8 | B43: A23-171-B | C43: (2640) 9 5/8" X 8 5/8" SD BEVELED REDUCING INSERT | D43: Keystone | E43: 200 | F43: 150 | G43: =IF($E43=0,0,$F43/$E43*$F$13) -> 0.3402 | H43: 4.68 | I43: 0 | J43: =$H43*$F$8*($F$9*$F$10/$F$11)+IF($H$52=0,0,'Bank Fee'!$H$8*$H43/$H$52) -> 0.026767472 | K43: =IF($G$52=0,0,(Logistic!$M$6+Logistic!$R$6)*$G43/$G$52) -> 0.35140783 | L43: =($H43+$K43)*$I43 -> 0 | M43: =$F$6*$P43 -> #VALUE! | N43: =$F$7*$M43 -> #VALUE! | O43: =$H43+$J43+$K43+$L43+$M43+$N43 -> #VALUE! | P43: =ROUNDUP(($H43+$J43+$K43+$L43)/(1-$F$5-$F$6*(1+$F$7)),2) -> #VALUE! | Q43: =ROUNDUP($P43*$F$3/$F$12,0)*$F$12 -> #VALUE! | R43: =$E43*$Q43 -> #VALUE! | S43: =$P43-$O43 -> #VALUE! | T43: =IF($P43=0,0,$S43/$P43) -> #VALUE! | U43: =$E43*$S43 -> #VALUE! | V43: =$E43*$O43 -> #VALUE!
A44: 9 | B44: A23-173 | C44: (2636) 14" X 13 3/8" SD INSERT | D44: Keystone | E44: 400 | F44: 248 | G44: =IF($E44=0,0,$F44/$E44*$F$13) -> 0.281232 | H44: 4.55 | I44: 0 | J44: =$H44*$F$8*($F$9*$F$10/$F$11)+IF($H$52=0,0,'Bank Fee'!$H$8*$H44/$H$52) -> 0.026023931 | K44: =IF($G$52=0,0,(Logistic!$M$6+Logistic!$R$6)*$G44/$G$52) -> 0.29049714 | L44: =($H44+$K44)*$I44 -> 0 | M44: =$F$6*$P44 -> #VALUE! | N44: =$F$7*$M44 -> #VALUE! | O44: =$H44+$J44+$K44+$L44+$M44+$N44 -> #VALUE! | P44: =ROUNDUP(($H44+$J44+$K44+$L44)/(1-$F$5-$F$6*(1+$F$7)),2) -> #VALUE! | Q44: =ROUNDUP($P44*$F$3/$F$12,0)*$F$12 -> #VALUE! | R44: =$E44*$Q44 -> #VALUE! | S44: =$P44-$O44 -> #VALUE! | T44: =IF($P44=0,0,$S44/$P44) -> #VALUE! | U44: =$E44*$S44 -> #VALUE! | V44: =$E44*$O44 -> #VALUE!
A45: 10 | B45: A23-173-B | C45: (2636) 14" X 13 3/8" SD BEVELED INSERT | D45: Keystone | E45: 200 | F45: 128 | G45: =IF($E45=0,0,$F45/$E45*$F$13) -> 0.290304 | H45: 4.73 | I45: 0 | J45: =$H45*$F$8*($F$9*$F$10/$F$11)+IF($H$52=0,0,'Bank Fee'!$H$8*$H45/$H$52) -> 0.027053449 | K45: =IF($G$52=0,0,(Logistic!$M$6+Logistic!$R$6)*$G45/$G$52) -> 0.29986802 | L45: =($H45+$K45)*$I45 -> 0 | M45: =$F$6*$P45 -> #VALUE! | N45: =$F$7*$M45 -> #VALUE! | O45: =$H45+$J45+$K45+$L45+$M45+$N45 -> #VALUE! | P45: =ROUNDUP(($H45+$J45+$K45+$L45)/(1-$F$5-$F$6*(1+$F$7)),2) -> #VALUE! | Q45: =ROUNDUP($P45*$F$3/$F$12,0)*$F$12 -> #VALUE! | R45: =$E45*$Q45 -> #VALUE! | S45: =$P45-$O45 -> #VALUE! | T45: =IF($P45=0,0,$S45/$P45) -> #VALUE! | U45: =$E45*$S45 -> #VALUE! | V45: =$E45*$O45 -> #VALUE!
...

Sheet Logistic
A1: LOGISTIC — FREIGHT & INSURANCE COST POOL
A2: Chữ xanh dương = input · đen = công thức · xanh lá = link sang Margin Analysis
A4: Shipment | B4: Weight (kg) | C4: From | D4: To | E4: MOT | F4: Forwarder | G4: Fixed charge (USD) | H4: Rate (USD/kg) | I4: Chargeable weight (kg) | J4: FREIGHT (USD) | K4: Clearance (USD) | L4: Inland (USD) | M4: Total Logistic (USD) | N4: USD/kg | O4: Goods value (USD) | P4: % Insured value | Q4: Insurance rate | R4: Min insurance (USD) | S4: Insurance (USD) | T4: Total Logistic + Insurance
A5: Shipment 1 | B5: ='Margin Analysis'!$G$31 -> 1031.0328 | C5: US | D5: VN | E5: AIR FREIGHT | F5: OTHERS | G5: 500 | H5: 2.5 | I5: 1300 | J5: =G5+H5*I5 -> 3750 | K5: 150 | L5: 100 | M5: =J5+K5+L5 -> 4000 | N5: =IF(B5=0,0,M5/B5) -> 3.879605 | O5: ='Margin Analysis'!$H$31 -> 19271.2 | P5: 1.1 | Q5: 0.0001 | R5: 15 | S5: =MAX((O5+M5)*P5*Q5,R5) -> 15 | T5: =M5+S5 -> 4015
A6: Shipment 2 | B6: ='Margin Analysis'!$G$52 -> 1031.0328 | C6: US | D6: VN | E6: SEA FREIGHT | F6: OTHERS | G6: 800 | H6: 0 | I6: 0 | J6: =G6+H6*I6 -> 800 | K6: 150 | L6: 100 | M6: =J6+K6+L6 -> 1050 | N6: =IF(B6=0,0,M6/B6) -> 1.0183963 | O6: ='Margin Analysis'!$H$52 -> 19271.2 | P6: 1.1 | Q6: 0.0001 | R6: 15 | S6: =MAX((O6+M6)*P6*Q6,R6) -> 15 | T6: =M6+S6 -> 1065
A9: Ghi chú:
A10: • Cột B (Weight) và cột O (Goods value) tự lấy từ sheet Margin Analysis — không sửa tay.
A11: • Cột I "Chargeable weight" là trọng lượng quy đổi thể tích do forwarder báo (air: 1.300 kg). Nhập tay.
A12: • Cước SEA nhập trọn gói ở cột G (Fixed charge), để Rate H = 0 và Chargeable weight I = 0.
A13: • Insurance = MAX((Goods value + FREIGHT) × 110% × 0,01% ; Min 15 USD).
A14: • Cột T (Total Logistic + Insurance) là pool mà sheet Margin Analysis phân bổ cho từng dòng theo trọng lượng.

Sheet Bank Fee
A1: BANK FEE
A2: Bank: MBBANK
A4: No. | B4: Description | C4: Rate | D4: VAT factor | E4: Min fee (USD) | F4: Base amount (USD) | G4: Condition | H4: Fee (USD)
A5: 1 | B5: International remittance (pay supplier) | C5: 0.002 | D5: 1.1 | E5: 50 | F5: ='Margin Analysis'!$H$31 -> 19271.2 | G5: Applies only when Goods origin ≠ "Local" | H5: =IF('Margin Analysis'!$B$6="Local",0,MAX(C5*D5*F5,E5)) -> 50
A6: 2 | B6: International receive (from customer) | C6: 0.0005 | D6: 1 | E6: 5 | F6: 0 | G6: Applies only when Country ≠ "VN" | H6: =IF('Margin Analysis'!$B$5="VN",0,MAX(C6*D6*F6,E6)) -> 0
A7: 3 | B7: Other bank charges | H7: 0
B8: TOTAL BANK FEE | H8: =SUM(H5:H7) -> 50
A11: Ghi chú:
A12: • Tỷ lệ 0,200% × hệ số VAT 1,1 = 0,220% — đúng công thức MBBank (0,2% phí + 10% VAT).
A13: • Base amount của International remittance = Total Material Cost (số tiền thực trả nhà cung cấp), lấy tự động từ Margin Analysis.
A14: • Base amount của International receive (F6) phải NHẬP TAY giá trị hợp đồng USD, không link tự động để tránh vòng lặp công thức (revenue → bank fee → unit cost → revenue).
A15: • File gốc ghi nhãn 0,05% nhưng công thức là 0,005%. Bản này dùng 0,05% — vui lòng xác nhận lại biểu phí với ngân hàng.
A16: • Ô H8 (TOTAL BANK FEE) được sheet Margin Analysis phân bổ cho từng dòng theo tỷ trọng Material Cost.
